var test = {"uid":"test_9831494712706-36","reportElements":[{"title":"setUp","message":null,"status":"success","type":"startLevel","time":"2017-05-14"},{"title":"Test class before method","message":null,"status":"success","type":"regular","time":"2017-05-14"},{"title":null,"message":null,"status":"success","type":"stopLevel","time":"2017-05-14"},{"title":"About to fail","message":null,"status":"success","type":"regular","time":"2017-05-14"},{"title":"The test ended with the following exception:","message":"java.lang.Exception: This is my failure\r\n\tat il.co.topq.difido.DifidoReporterTestsPart1.testWithFailure(DifidoReporterTestsPart1.java:97)\r\n\tat sun.reflect.NativeMethodAccessorImpl.invoke0(Native Method)\r\n\tat sun.reflect.NativeMethodAccessorImpl.invoke(NativeMethodAccessorImpl.java:62)\r\n\tat sun.reflect.DelegatingMethodAccessorImpl.invoke(DelegatingMethodAccessorImpl.java:43)\r\n\tat java.lang.reflect.Method.invoke(Method.java:498)\r\n\tat org.testng.internal.MethodInvocationHelper.invokeMethod(MethodInvocationHelper.java:108)\r\n\tat org.testng.internal.Invoker.invokeMethod(Invoker.java:661)\r\n\tat org.testng.internal.Invoker.invokeTestMethod(Invoker.java:869)\r\n\tat org.testng.internal.TestMethodWithDataProviderMethodWorker.call(TestMethodWithDataProviderMethodWorker.java:75)\r\n\tat org.testng.internal.TestMethodWithDataProviderMethodWorker.call(TestMethodWithDataProviderMethodWorker.java:14)\r\n\tat java.util.concurrent.FutureTask.run(FutureTask.java:266)\r\n\tat java.util.concurrent.Executors$RunnableAdapter.call(Executors.java:511)\r\n\tat java.util.concurrent.FutureTask.run(FutureTask.java:266)\r\n\tat java.util.concurrent.ThreadPoolExecutor.runWorker(ThreadPoolExecutor.java:1142)\r\n\tat java.util.concurrent.ThreadPoolExecutor$Worker.run(ThreadPoolExecutor.java:617)\r\n\tat java.lang.Thread.run(Thread.java:745)\r\n","status":"failure","type":"regular","time":"2017-05-14"}]};